Workbook

Sheet Posouzení PREFIX
A1: Posouzení main carrieru – PREFIX
A2: Datum posouzení:
A3: Kód vady | B3: SSP2 | C3: PMEP | D3: OHN2 | E3: PSKU | F3: PDSP | G3: PLPK | H3: PSNA | I3: LEP | J3: PVZD | K3: PSMK | L3: ZVR | M3: LAB | N3: PKOL | O3: PELC | P3: PDEP | Q3: PNHE | R3: PELC2 | S3: PVZD2 | T3: PSKU2 | U3: PPOS | V3: PDEP2 | W3: OTL | X3: POTL2 | Y3: NRW | Z3: SPF | AA3: DEL | AB3: PDEL | AC3: ZHN | AD3: PSZA | AE3: ZNA | AF3: PLPK2 | AG3: FLEK | AH3: P022 | AI3: PSPC | AJ3: PSKZ | AK3: PSHC | AL3: PSMC | AM3: PSMC2 | AN3: PELS | AO3: PELS2 | AP3: PSGL | AQ3: PDSP2 | AR3: PSPS | AS3: PSAL | AT3: KRSW | AU3: KRSK | AV3: KRSS | AW3: _MES | AX3: _ROK
A4: Popis vady | B4: Spálený spacer | C4: Mechanické poškození | D4: Odřená hrana | E4: Spálená kůže | F4: Deformovaný spacer | G4: Lepidlo pod kůží | H4: Špatný nástřih | I4: Špatně nanesené lepidlo | J4: Vzduch | K4: Šev mimo kanál | L4: Zvrásnění povrchu | M4: Testy laboratoř | N4: Kontaminace lepidlem | O4: Expirované lepidlo na MC | P4: Deformace plastu | Q4: Nefunkční heating | R4: Expirované lepidlo na main carrieru (stroj) | S4: Vzduch (stroj) | T4: Spálená kůže (stroj) | U4: Poškozené šití | V4: Deformace plastu (stroj) | W4: Otlak | X4: Otlak (stroj) | Y4: NOK rework | Z4: Špatný prefix | AA4: Delaminace (hrany) | AB4: Delaminace (plochy) | AC4: Zahranění NOK | AD4: Špatný zaříznutí | AE4: Znečištění od ASQ | AF4: Lepidlo pod kůží (stroj) | AG4: Flek | AH4: Flek (stroj) | AI4: Špatný spacer | AJ4: Špatná kůže | AK4: Špatný heating spacer | AL4: Špatný plastový MC | AM4: Špatný plastový MC (stroj) | AN4: Expirované lepidlo na spaceru | AO4: Expirované lepidlo na spaceru (stroj) | AP4: Špatná gramáž lepidla | AQ4: Deformovaný spacer (stroj) | AR4: Špatný prefix spaceru (otlak, mimo pozici) | AS4: Špatně aktivované lepidlo | AT4: Kragujevac - sewing | AU4: Kragujevac - skin defect | AV4: Kragujevac - short skin | AW4: Měsíc | AX4: Rok
A5: Datum / Part number
A6: 46174 | F6: MY0547099-9Z03 | H6: 3449518-9Y982705260127 | O6: 3449518-9Z032805260042 | AR6: 3449523-9Y52 | AT6: MY0547099-9Y512805260076 | AU6: 3448362-9Y523105260001 | AW6: =IF(A6="","",IF(ISNUMBER(A6),MONTH(A6),IFERROR(VALUE(MID(A6,FIND(".",A6)+1,FIND(".",A6,FIND(".",A6)+1)-FIND(".",A6)-1)),""))) -> 6 | AX6: =IF(A6="","",IF(ISNUMBER(A6),YEAR(A6),IFERROR(VALUE(RIGHT(A6,4)),""))) -> 2026
A7: 46174 | AU7: 3448362-9Y983105260009 | AW7: =IF(A7="","",IF(ISNUMBER(A7),MONTH(A7),IFERROR(VALUE(MID(A7,FIND(".",A7)+1,FIND(".",A7,FIND(".",A7)+1)-FIND(".",A7)-1)),""))) -> 6 | AX7: =IF(A7="","",IF(ISNUMBER(A7),YEAR(A7),IFERROR(VALUE(RIGHT(A7,4)),""))) -> 2026
A8: 46174 | AU8: 3448362-9Y983105260009 | AW8: =IF(A8="","",IF(ISNUMBER(A8),MONTH(A8),IFERROR(VALUE(MID(A8,FIND(".",A8)+1,FIND(".",A8,FIND(".",A8)+1)-FIND(".",A8)-1)),""))) -> 6 | AX8: =IF(A8="","",IF(ISNUMBER(A8),YEAR(A8),IFERROR(VALUE(RIGHT(A8,4)),""))) -> 2026
A9: 46175 | B9: MY0547078-9Z040106260069 | P9: MY0547078-8X820106260086 | Y9: 3449518-9Z040106260128 | Z9: MY0547099-9Z040206260037 | AR9: 3449523-9Y510106260035 | AU9: MY0547099-9Z030206260016 | AV9: 3449523-9Z030106260075 | AW9: =IF(A9="","",IF(ISNUMBER(A9),MONTH(A9),IFERROR(VALUE(MID(A9,FIND(".",A9)+1,FIND(".",A9,FIND(".",A9)+1)-FIND(".",A9)-1)),""))) -> 6 | AX9: =IF(A9="","",IF(ISNUMBER(A9),YEAR(A9),IFERROR(VALUE(RIGHT(A9,4)),""))) -> 2026
A10: 46175 | P10: MY0547078-9E380206260004 | Z10: 3449518-9Z040106260146 | AU10: MY0547099-9Y520106260114 | AV10: 3449518-9Z030106260045 | AW10: =IF(A10="","",IF(ISNUMBER(A10),MONTH(A10),IFERROR(VALUE(MID(A10,FIND(".",A10)+1,FIND(".",A10,FIND(".",A10)+1)-FIND(".",A10)-1)),""))) -> 6 | AX10: =IF(A10="","",IF(ISNUMBER(A10),YEAR(A10),IFERROR(VALUE(RIGHT(A10,4)),""))) -> 2026
A11: 46175 | P11: 3449518-9Y51 | AV11: 3449523-9Y520106260111 | AW11: =IF(A11="","",IF(ISNUMBER(A11),MONTH(A11),IFERROR(VALUE(MID(A11,FIND(".",A11)+1,FIND(".",A11,FIND(".",A11)+1)-FIND(".",A11)-1)),""))) -> 6 | AX11: =IF(A11="","",IF(ISNUMBER(A11),YEAR(A11),IFERROR(VALUE(RIGHT(A11,4)),""))) -> 2026
A12: 46175 | AV12: 3449518-9Z040106260119 | AW12: =IF(A12="","",IF(ISNUMBER(A12),MONTH(A12),IFERROR(VALUE(MID(A12,FIND(".",A12)+1,FIND(".",A12,FIND(".",A12)+1)-FIND(".",A12)-1)),""))) -> 6 | AX12: =IF(A12="","",IF(ISNUMBER(A12),YEAR(A12),IFERROR(VALUE(RIGHT(A12,4)),""))) -> 2026
A13: 46175 | AV13: 3449518-9Z040106260127 | AW13: =IF(A13="","",IF(ISNUMBER(A13),MONTH(A13),IFERROR(VALUE(MID(A13,FIND(".",A13)+1,FIND(".",A13,FIND(".",A13)+1)-FIND(".",A13)-1)),""))) -> 6 | AX13: =IF(A13="","",IF(ISNUMBER(A13),YEAR(A13),IFERROR(VALUE(RIGHT(A13,4)),""))) -> 2026
A14: 46175 | AV14: MY0547099-9Z040206260045 | AW14: =IF(A14="","",IF(ISNUMBER(A14),MONTH(A14),IFERROR(VALUE(MID(A14,FIND(".",A14)+1,FIND(".",A14,FIND(".",A14)+1)-FIND(".",A14)-1)),""))) -> 6 | AX14: =IF(A14="","",IF(ISNUMBER(A14),YEAR(A14),IFERROR(VALUE(RIGHT(A14,4)),""))) -> 2026
A15: 46176 | B15: MY0547099-9Z22 | E15: MY0547078-9Y980206260101 | P15: MY0547078-8X820206260032 | Z15: MY0547099-9E380306260003 | AF15: M3449523-9Z220306260026 | AT15: 3449518-9Y520206260061 | AU15: 3449518-9Y520206260078 | AV15: MY0547099-9E380306260001 | AW15: =IF(A15="","",IF(ISNUMBER(A15),MONTH(A15),IFERROR(VALUE(MID(A15,FIND(".",A15)+1,FIND(".",A15,FIND(".",A15)+1)-FIND(".",A15)-1)),""))) -> 6 | AX15: =IF(A15="","",IF(ISNUMBER(A15),YEAR(A15),IFERROR(VALUE(RIGHT(A15,4)),""))) -> 2026
A16: 46176 | Z16: MY0547078-9Z040206260106 | AT16: 3449518-9Y740206260087 | AU16: MY0547078-9Z040206260105 | AW16: =IF(A16="","",IF(ISNUMBER(A16),MONTH(A16),IFERROR(VALUE(MID(A16,FIND(".",A16)+1,FIND(".",A16,FIND(".",A16)+1)-FIND(".",A16)-1)),""))) -> 6 | AX16: =IF(A16="","",IF(ISNUMBER(A16),YEAR(A16),IFERROR(VALUE(RIGHT(A16,4)),""))) -> 2026
A17: 46176 | AT17: 3449518-9Y510206260162 | AU17: 3449518-9Y510206260156 | AW17: =IF(A17="","",IF(ISNUMBER(A17),MONTH(A17),IFERROR(VALUE(MID(A17,FIND(".",A17)+1,FIND(".",A17,FIND(".",A17)+1)-FIND(".",A17)-1)),""))) -> 6 | AX17: =IF(A17="","",IF(ISNUMBER(A17),YEAR(A17),IFERROR(VALUE(RIGHT(A17,4)),""))) -> 2026
A18: 46176 | AU18: MY0547099-9Z220206260132 | AW18: =IF(A18="","",IF(ISNUMBER(A18),MONTH(A18),IFERROR(VALUE(MID(A18,FIND(".",A18)+1,FIND(".",A18,FIND(".",A18)+1)-FIND(".",A18)-1)),""))) -> 6 | AX18: =IF(A18="","",IF(ISNUMBER(A18),YEAR(A18),IFERROR(VALUE(RIGHT(A18,4)),""))) -> 2026
A19: 46177 | C19: MY0547078-9E380406260020 | F19: MY0547099-9Y510306260132 | J19: MY0547099-9Y510306260145 | Z19: 3448362-9Y980306260010 | AT19: 3448362-9Y980306260007 | AU19: MY0547078-9Y510406260036 | AV19: 3449518-9Y510306260015 | AW19: =IF(A19="","",IF(ISNUMBER(A19),MONTH(A19),IFERROR(VALUE(MID(A19,FIND(".",A19)+1,FIND(".",A19,FIND(".",A19)+1)-FIND(".",A19)-1)),""))) -> 6 | AX19: =IF(A19="","",IF(ISNUMBER(A19),YEAR(A19),IFERROR(VALUE(RIGHT(A19,4)),""))) -> 2026
A20: 46177 | F20: 3449518-9Y520306260028 | AU20: MY0547078-8X820406260026 | AW20: =IF(A20="","",IF(ISNUMBER(A20),MONTH(A20),IFERROR(VALUE(MID(A20,FIND(".",A20)+1,FIND(".",A20,FIND(".",A20)+1)-FIND(".",A20)-1)),""))) -> 6 | AX20: =IF(A20="","",IF(ISNUMBER(A20),YEAR(A20),IFERROR(VALUE(RIGHT(A20,4)),""))) -> 2026
A21: 46177 | AU21: MY0547078-9E380406260019 | AW21: =IF(A21="","",IF(ISNUMBER(A21),MONTH(A21),IFERROR(VALUE(MID(A21,FIND(".",A21)+1,FIND(".",A21,FIND(".",A21)+1)-FIND(".",A21)-1)),""))) -> 6 | AX21: =IF(A21="","",IF(ISNUMBER(A21),YEAR(A21),IFERROR(VALUE(RIGHT(A21,4)),""))) -> 2026
A22: 46177 | AU22: 3448356-9Y520306260010 | AW22: =IF(A22="","",IF(ISNUMBER(A22),MONTH(A22),IFERROR(VALUE(MID(A22,FIND(".",A22)+1,FIND(".",A22,FIND(".",A22)+1)-FIND(".",A22)-1)),""))) -> 6 | AX22: =IF(A22="","",IF(ISNUMBER(A22),YEAR(A22),IFERROR(VALUE(RIGHT(A22,4)),""))) -> 2026
A23: 46177 | AU23: 3449523-9Y520306260067 | AW23: =IF(A23="","",IF(ISNUMBER(A23),MONTH(A23),IFERROR(VALUE(MID(A23,FIND(".",A23)+1,FIND(".",A23,FIND(".",A23)+1)-FIND(".",A23)-1)),""))) -> 6 | AX23: =IF(A23="","",IF(ISNUMBER(A23),YEAR(A23),IFERROR(VALUE(RIGHT(A23,4)),""))) -> 2026
A24: 46177 | AU24: 3449523-9Y520306260101 | AW24: =IF(A24="","",IF(ISNUMBER(A24),MONTH(A24),IFERROR(VALUE(MID(A24,FIND(".",A24)+1,FIND(".",A24,FIND(".",A24)+1)-FIND(".",A24)-1)),""))) -> 6 | AX24: =IF(A24="","",IF(ISNUMBER(A24),YEAR(A24),IFERROR(VALUE(RIGHT(A24,4)),""))) -> 2026
A25: 46177 | AU25: MY0547099-9Y510306260137 | AW25: =IF(A25="","",IF(ISNUMBER(A25),MONTH(A25),IFERROR(VALUE(MID(A25,FIND(".",A25)+1,FIND(".",A25,FIND(".",A25)+1)-FIND(".",A25)-1)),""))) -> 6 | AX25: =IF(A25="","",IF(ISNUMBER(A25),YEAR(A25),IFERROR(VALUE(RIGHT(A25,4)),""))) -> 2026
A26: 46178 | B26: 3449518-9E380506260052 | C26: MY0547099-9Z030406260069 | P26: MY0547078-9Z220506260016 | Z26: MY0547099-9E380406260120 | AR26: 3449518-9Z030406260119 | AT26: MY0547099-9Z220406260100 | AU26: 3449523-9E380406260066 | AV26: 3449518-9Y980406260144 | AW26: =IF(A26="","",IF(ISNUMBER(A26),MONTH(A26),IFERROR(VALUE(MID(A26,FIND(".",A26)+1,FIND(".",A26,FIND(".",A26)+1)-FIND(".",A26)-1)),""))) -> 6 | AX26: =IF(A26="","",IF(ISNUMBER(A26),YEAR(A26),IFERROR(VALUE(RIGHT(A26,4)),""))) -> 2026
A27: 46178 | B27: MY0547078-8X820506260030 | P27: MY0547078-8X820506260019 | Z27: 3449518-9E380506260056 | AT27: 3449523-9Y820506260005 | AU27: 3449523-9Y510406260014 | AV27: 3449523-9Y520406260110 | AW27: =IF(A27="","",IF(ISNUMBER(A27),MONTH(A27),IFERROR(VALUE(MID(A27,FIND(".",A27)+1,FIND(".",A27,FIND(".",A27)+1)-FIND(".",A27)-1)),""))) -> 6 | AX27: =IF(A27="","",IF(ISNUMBER(A27),YEAR(A27),IFERROR(VALUE(RIGHT(A27,4)),""))) -> 2026
A28: 46178 | P28: MY0547078-8X820506260017 | AU28: 3449523-9Y520406260085 | AV28: MY0547099-9Z030406260066 | AW28: =IF(A28="","",IF(ISNUMBER(A28),MONTH(A28),IFERROR(VALUE(MID(A28,FIND(".",A28)+1,FIND(".",A28,FIND(".",A28)+1)-FIND(".",A28)-1)),""))) -> 6 | AX28: =IF(A28="","",IF(ISNUMBER(A28),YEAR(A28),IFERROR(VALUE(RIGHT(A28,4)),""))) -> 2026
A29: 46178 | P29: MY0547099-8X820406260119 | AU29: M3449518-9Z220506260036 | AV29: MY0547099-8X820406260118 | AW29: =IF(A29="","",IF(ISNUMBER(A29),MONTH(A29),IFERROR(VALUE(MID(A29,FIND(".",A29)+1,FIND(".",A29,FIND(".",A29)+1)-FIND(".",A29)-1)),""))) -> 6 | AX29: =IF(A29="","",IF(ISNUMBER(A29),YEAR(A29),IFERROR(VALUE(RIGHT(A29,4)),""))) -> 2026
A30: 46178 | AU30: 3449518-9Z030406260070 | AV30: MY0547099-9E380506260011 | AW30: =IF(A30="","",IF(ISNUMBER(A30),MONTH(A30),IFERROR(VALUE(MID(A30,FIND(".",A30)+1,FIND(".",A30,FIND(".",A30)+1)-FIND(".",A30)-1)),""))) -> 6 | AX30: =IF(A30="","",IF(ISNUMBER(A30),YEAR(A30),IFERROR(VALUE(RIGHT(A30,4)),""))) -> 2026
A31: 46181 | C31: 3449523-9Z030506260047 | Y31: MY0547078-9E380806260037 | Z31: 3449523-9Y530506260004 | AU31: MY0547078-9Y520506260134 | AV31: 3448362-8X820806260001 | AW31: =IF(A31="","",IF(ISNUMBER(A31),MONTH(A31),IFERROR(VALUE(MID(A31,FIND(".",A31)+1,FIND(".",A31,FIND(".",A31)+1)-FIND(".",A31)-1)),""))) -> 6 | AX31: =IF(A31="","",IF(ISNUMBER(A31),YEAR(A31),IFERROR(VALUE(RIGHT(A31,4)),""))) -> 2026
A32: 46181 | Z32: MY0547078-9Y51 | AU32: MY0547099-9E380506260018 | AW32: =IF(A32="","",IF(ISNUMBER(A32),MONTH(A32),IFERROR(VALUE(MID(A32,FIND(".",A32)+1,FIND(".",A32,FIND(".",A32)+1)-FIND(".",A32)-1)),""))) -> 6 | AX32: =IF(A32="","",IF(ISNUMBER(A32),YEAR(A32),IFERROR(VALUE(RIGHT(A32,4)),""))) -> 2026
A33: 46181 | AU33: MY0547099-9Y520506260035 | AW33: =IF(A33="","",IF(ISNUMBER(A33),MONTH(A33),IFERROR(VALUE(MID(A33,FIND(".",A33)+1,FIND(".",A33,FIND(".",A33)+1)-FIND(".",A33)-1)),""))) -> 6 | AX33: =IF(A33="","",IF(ISNUMBER(A33),YEAR(A33),IFERROR(VALUE(RIGHT(A33,4)),""))) -> 2026
A34: 46181 | AU34: MY0547099-9Y820506260051 | AW34: =IF(A34="","",IF(ISNUMBER(A34),MONTH(A34),IFERROR(VALUE(MID(A34,FIND(".",A34)+1,FIND(".",A34,FIND(".",A34)+1)-FIND(".",A34)-1)),""))) -> 6 | AX34: =IF(A34="","",IF(ISNUMBER(A34),YEAR(A34),IFERROR(VALUE(RIGHT(A34,4)),""))) -> 2026
A35: 46181 | AU35: MY0547078-9Y520706260012 | AW35: =IF(A35="","",IF(ISNUMBER(A35),MONTH(A35),IFERROR(VALUE(MID(A35,FIND(".",A35)+1,FIND(".",A35,FIND(".",A35)+1)-FIND(".",A35)-1)),""))) -> 6 | AX35: =IF(A35="","",IF(ISNUMBER(A35),YEAR(A35),IFERROR(VALUE(RIGHT(A35,4)),""))) -> 2026
A36: 46181 | AU36: 3449523-9Z030506260034 | AW36: =IF(A36="","",IF(ISNUMBER(A36),MONTH(A36),IFERROR(VALUE(MID(A36,FIND(".",A36)+1,FIND(".",A36,FIND(".",A36)+1)-FIND(".",A36)-1)),""))) -> 6 | AX36: =IF(A36="","",IF(ISNUMBER(A36),YEAR(A36),IFERROR(VALUE(RIGHT(A36,4)),""))) -> 2026
A37: 46182 | B37: 3449518-9Y980906260017 | C37: 3449523-9Z030506260042 | E37: 3448356-9Y520806260011 | F37: MY0547078-9E380906260011 | Y37: 3448356-9Y520806260021 | Z37: M3449523-9Z230806260146 | AU37: M3449523-9Z230806260076 | AV37: MY0547078-9A840906260006 | AW37: =IF(A37="","",IF(ISNUMBER(A37),MONTH(A37),IFERROR(VALUE(MID(A37,FIND(".",A37)+1,FIND(".",A37,FIND(".",A37)+1)-FIND(".",A37)-1)),""))) -> 6 | AX37: =IF(A37="","",IF(ISNUMBER(A37),YEAR(A37),IFERROR(VALUE(RIGHT(A37,4)),""))) -> 2026
A38: 46182 | B38: 3449518-9Y740806260065 | E38: MY0547099-9Y520806260034 | F38: 3449518-9E380506260108 | AU38: 3449518-9Y740806260102 | AV38: 3449523-8X820806260106 | AW38: =IF(A38="","",IF(ISNUMBER(A38),MONTH(A38),IFERROR(VALUE(MID(A38,FIND(".",A38)+1,FIND(".",A38,FIND(".",A38)+1)-FIND(".",A38)-1)),""))) -> 6 | AX38: =IF(A38="","",IF(ISNUMBER(A38),YEAR(A38),IFERROR(VALUE(RIGHT(A38,4)),""))) -> 2026
A39: 46182 | B39: 3449518-9Y740806260078 | AU39: 3449518-9Y980806260114 | AV39: 3449523-9Y980806260059 | AW39: =IF(A39="","",IF(ISNUMBER(A39),MONTH(A39),IFERROR(VALUE(MID(A39,FIND(".",A39)+1,FIND(".",A39,FIND(".",A39)+1)-FIND(".",A39)-1)),""))) -> 6 | AX39: =IF(A39="","",IF(ISNUMBER(A39),YEAR(A39),IFERROR(VALUE(RIGHT(A39,4)),""))) -> 2026
A40: 46182 | AU40: 3449518-9Y740906260031 | AV40: M3449523-9Z220806260029 | AW40: =IF(A40="","",IF(ISNUMBER(A40),MONTH(A40),IFERROR(VALUE(MID(A40,FIND(".",A40)+1,FIND(".",A40,FIND(".",A40)+1)-FIND(".",A40)-1)),""))) -> 6 | AX40: =IF(A40="","",IF(ISNUMBER(A40),YEAR(A40),IFERROR(VALUE(RIGHT(A40,4)),""))) -> 2026
...

Sheet Posouzení SKLAD
A1: Posouzení main carrieru – SKLAD
A2: Datum posouzení:
A3: Kód vady | B3: SSP2 | C3: PMEP | D3: OHN2+D3 | E3: PSKU | F3: PDSP | G3: PSNA | H3: LEP | I3: PVZD | J3: PSMK | K3: ZVR | L3: LAB | M3: PKOL | N3: PELC | O3: PDEP | P3: PNHE | Q3: PELC2 | R3: PELC2 | S3: PSKU2 | T3: PPOS | U3: PDSP2 | V3: OTL | W3: NRW | X3: SPF | Y3: POTL2 | Z3: DEL | AA3: PDEL | AB3: ZHN | AC3: PSNA | AD3: ZNA | AE3: PLPK2 | AF3: FLEK | AG3: P022 | AH3: PSPC | AI3: PSKZ | AJ3: PSHC | AK3: PSMC | AL3: PSMC2 | AM3: PELS | AN3: PELS2 | AO3: PSGL | AP3: PDSP2 | AQ3: PSPS | AR3: PSAL | AS3: PSNA | AT3: PLPK | AU3: KRSW | AV3: KRSK | AW3: KRSS | AX3: _MES | AY3: _ROK
A4: Popis vady | B4: Spálený spacer | C4: Mechanické poškození | D4: Odřená hrana | E4: Spálená kůže | F4: Deformovaný spacer | G4: Špatný nástřih | H4: Špatně nanesené lepidlo | I4: Vzduch | J4: Šev mimo kanál | K4: Zvrásnění povrchu | L4: Testy laboratoř | M4: Kontaminace lepidlem | N4: Expirované lepidlo na MC | O4: Deformace plastu | P4: Nefunkční heating | Q4: Expirované lepidlo na main carrieru (stroj) | R4: Expirované lepidlo na main carrieru (stroj) | S4: Spálená kůže (stroj) | T4: Poškozené šití | U4: Deformace plastu (stroj) | V4: Otlak | W4: NOK rework | X4: Špatný prefix | Y4: Otlak (stroj) | Z4: Delaminace (hrany) | AA4: Delaminace (plochy) | AB4: Zahranění NOK | AC4: Špatný zaříznutí | AD4: Znečištění od ASQ | AE4: Lepidlo pod kůží (stroj) | AF4: Flek | AG4: Flek (stroj) | AH4: Špatný spacer | AI4: Špatná kůže | AJ4: Špatný heating spacer | AK4: Špatný plastový MC | AL4: Špatný plastový MC (stroj) | AM4: Expirované lepidlo na spaceru | AN4: Expirované lepidlo na spaceru (stroj) | AO4: Špatná gramáž lepidla | AP4: Deformovaný spacer (stroj) | AQ4: spatny prefix spaceru | AR4: Špatně aktivované lepidlo | AS4: Špatný zaříznutí | AT4: Lepidlo pod kuzi | AU4: Kragujevac - sewing | AV4: Kragujevac - skin defect | AW4: Kragujevac - short skin | AX4: Měsíc | AY4: Rok | AZ4: \loose leather
A5: Datum / Part number
A6: 46174 | F6: 3449518-9Y522605260012 | I6: 3449518-9Z032505260080 | X6: MY0547099-9Y512505260073 | AQ6: MY0547078-8X822505260145 | AS6: 3449518-9E382505260095 | AT6: 3448362-9Y522605260032 | AU6: MY0547078-9Y522605260058 | AV6: 3448362-9Y742605260039 | AX6: =IF(A6="","",IF(ISNUMBER(A6),MONTH(A6),IFERROR(VALUE(MID(A6,FIND(".",A6)+1,FIND(".",A6,FIND(".",A6)+1)-FIND(".",A6)-1)),""))) -> 6 | AY6: =IF(A6="","",IF(ISNUMBER(A6),YEAR(A6),IFERROR(VALUE(RIGHT(A6,4)),""))) -> 2026
A7: 46174 | E7: MY0547078-9Y980406260073 | F7: MY0547078-9Z032505260092 | I7: MY0547078-9Y982505260117 | X7: 3449518-9E382505260099 | AV7: MY0547078-9Y522605260067 | AX7: =IF(A7="","",IF(ISNUMBER(A7),MONTH(A7),IFERROR(VALUE(MID(A7,FIND(".",A7)+1,FIND(".",A7,FIND(".",A7)+1)-FIND(".",A7)-1)),""))) -> 6 | AY7: =IF(A7="","",IF(ISNUMBER(A7),YEAR(A7),IFERROR(VALUE(RIGHT(A7,4)),""))) -> 2026
A8: 46174 | F8: MY0547099-9Z032505260032 | AX8: =IF(A8="","",IF(ISNUMBER(A8),MONTH(A8),IFERROR(VALUE(MID(A8,FIND(".",A8)+1,FIND(".",A8,FIND(".",A8)+1)-FIND(".",A8)-1)),""))) -> 6 | AY8: =IF(A8="","",IF(ISNUMBER(A8),YEAR(A8),IFERROR(VALUE(RIGHT(A8,4)),""))) -> 2026
A9: 46175 | B9: 3449518-9Y512705260114 | F9: 3449518-8X822705260065 | O9: MY0547099-9Z232705260150 | X9: 3448356-9Y982705260012 | AF9: MY0547099-9Y512705260023 | AS9: MY0547099-8X822605260027 | AV9: 3449523-9Z042605260024 | AW9: MY0547099-9E382705260101 | AX9: =IF(A9="","",IF(ISNUMBER(A9),MONTH(A9),IFERROR(VALUE(MID(A9,FIND(".",A9)+1,FIND(".",A9,FIND(".",A9)+1)-FIND(".",A9)-1)),""))) -> 6 | AY9: =IF(A9="","",IF(ISNUMBER(A9),YEAR(A9),IFERROR(VALUE(RIGHT(A9,4)),""))) -> 2026
A10: 46175 | F10: MY0547099-9Y982705260060 | AV10: 3448362-9Y981905260032 | AX10: =IF(A10="","",IF(ISNUMBER(A10),MONTH(A10),IFERROR(VALUE(MID(A10,FIND(".",A10)+1,FIND(".",A10,FIND(".",A10)+1)-FIND(".",A10)-1)),""))) -> 6 | AY10: =IF(A10="","",IF(ISNUMBER(A10),YEAR(A10),IFERROR(VALUE(RIGHT(A10,4)),""))) -> 2026
A11: 46175 | AV11: 3448362-9Y982605260001 | AX11: =IF(A11="","",IF(ISNUMBER(A11),MONTH(A11),IFERROR(VALUE(MID(A11,FIND(".",A11)+1,FIND(".",A11,FIND(".",A11)+1)-FIND(".",A11)-1)),""))) -> 6 | AY11: =IF(A11="","",IF(ISNUMBER(A11),YEAR(A11),IFERROR(VALUE(RIGHT(A11,4)),""))) -> 2026
A12: 46175 | AV12: MY0547078-8X822605260010 | AX12: =IF(A12="","",IF(ISNUMBER(A12),MONTH(A12),IFERROR(VALUE(MID(A12,FIND(".",A12)+1,FIND(".",A12,FIND(".",A12)+1)-FIND(".",A12)-1)),""))) -> 6 | AY12: =IF(A12="","",IF(ISNUMBER(A12),YEAR(A12),IFERROR(VALUE(RIGHT(A12,4)),""))) -> 2026
A13: 46175 | AV13: 3449518-9Y512705260106 | AX13: =IF(A13="","",IF(ISNUMBER(A13),MONTH(A13),IFERROR(VALUE(MID(A13,FIND(".",A13)+1,FIND(".",A13,FIND(".",A13)+1)-FIND(".",A13)-1)),""))) -> 6 | AY13: =IF(A13="","",IF(ISNUMBER(A13),YEAR(A13),IFERROR(VALUE(RIGHT(A13,4)),""))) -> 2026
A14: 46176 | F14: MY0547078-9Z042805260026 | X14: MY0547099-9Z222805260066 | AQ14: MY0547078-9E382705260077 | AU14: MY0547099-9Z222805260073 | AV14: MY0547099-9Z042805260055 | AW14: 3449523-8X822805260151 | AX14: =IF(A14="","",IF(ISNUMBER(A14),MONTH(A14),IFERROR(VALUE(MID(A14,FIND(".",A14)+1,FIND(".",A14,FIND(".",A14)+1)-FIND(".",A14)-1)),""))) -> 6 | AY14: =IF(A14="","",IF(ISNUMBER(A14),YEAR(A14),IFERROR(VALUE(RIGHT(A14,4)),""))) -> 2026
A15: 46176 | AQ15: MY0547099-9Y512805260105 | AX15: =IF(A15="","",IF(ISNUMBER(A15),MONTH(A15),IFERROR(VALUE(MID(A15,FIND(".",A15)+1,FIND(".",A15,FIND(".",A15)+1)-FIND(".",A15)-1)),""))) -> 6 | AY15: =IF(A15="","",IF(ISNUMBER(A15),YEAR(A15),IFERROR(VALUE(RIGHT(A15,4)),""))) -> 2026
A16: 46177 | C16: MY0547099-9E382805260034 | F16: MY0547078-9A842805260029 | I16: MY0547078-9Z032805260016 | X16: MY0547078-8X822805260043 | AQ16: MY0547099-9Z030106260064 | AU16: MY0547078-9Z042605260093 | AX16: =IF(A16="","",IF(ISNUMBER(A16),MONTH(A16),IFERROR(VALUE(MID(A16,FIND(".",A16)+1,FIND(".",A16,FIND(".",A16)+1)-FIND(".",A16)-1)),""))) -> 6 | AY16: =IF(A16="","",IF(ISNUMBER(A16),YEAR(A16),IFERROR(VALUE(RIGHT(A16,4)),""))) -> 2026
A17: 46177 | F17: MY0547078-9A842805260032 | I17: MY0547078-9Y742805260076 | AU17: MY0547099-9Y510106260092 | AX17: =IF(A17="","",IF(ISNUMBER(A17),MONTH(A17),IFERROR(VALUE(MID(A17,FIND(".",A17)+1,FIND(".",A17,FIND(".",A17)+1)-FIND(".",A17)-1)),""))) -> 6 | AY17: =IF(A17="","",IF(ISNUMBER(A17),YEAR(A17),IFERROR(VALUE(RIGHT(A17,4)),""))) -> 2026
A18: 46177 | F18: 3449518-9Z032805260043 | AU18: 3449518-9Z032805260074 | AX18: =IF(A18="","",IF(ISNUMBER(A18),MONTH(A18),IFERROR(VALUE(MID(A18,FIND(".",A18)+1,FIND(".",A18,FIND(".",A18)+1)-FIND(".",A18)-1)),""))) -> 6 | AY18: =IF(A18="","",IF(ISNUMBER(A18),YEAR(A18),IFERROR(VALUE(RIGHT(A18,4)),""))) -> 2026
A19: 46178 | F19: MY0547099-9Z040206260041 | I19: MY0547078-8X822805260068 | O19: MY0547099-9Z030106260056 | X19: M3448362-9Z220106260008 | AT19: 3449523-9Y980106260052 | AU19: 3449523-8X823105260008 | AW19: MY0547078-9Z030206260050 | AX19: =IF(A19="","",IF(ISNUMBER(A19),MONTH(A19),IFERROR(VALUE(MID(A19,FIND(".",A19)+1,FIND(".",A19,FIND(".",A19)+1)-FIND(".",A19)-1)),""))) -> 6 | AY19: =IF(A19="","",IF(ISNUMBER(A19),YEAR(A19),IFERROR(VALUE(RIGHT(A19,4)),""))) -> 2026
A20: 46178 | I20: MY0547099-9Z040206260038 | AU20: MY0547078-9Z040106260018 | AX20: =IF(A20="","",IF(ISNUMBER(A20),MONTH(A20),IFERROR(VALUE(MID(A20,FIND(".",A20)+1,FIND(".",A20,FIND(".",A20)+1)-FIND(".",A20)-1)),""))) -> 6 | AY20: =IF(A20="","",IF(ISNUMBER(A20),YEAR(A20),IFERROR(VALUE(RIGHT(A20,4)),""))) -> 2026
A21: 46181 | I21: MY0547078-8X820206260036 | W21: 3449523-9Z040206260010 | AQ21: MY0547099-9Z040206260125 | AV21: 3449523-9E380406260070 | AW21: 3448362-9Y520306260031 | AX21: =IF(A21="","",IF(ISNUMBER(A21),MONTH(A21),IFERROR(VALUE(MID(A21,FIND(".",A21)+1,FIND(".",A21,FIND(".",A21)+1)-FIND(".",A21)-1)),""))) -> 6 | AY21: =IF(A21="","",IF(ISNUMBER(A21),YEAR(A21),IFERROR(VALUE(RIGHT(A21,4)),""))) -> 2026
A22: 46181 | I22: MY0547099-9Y510106260101 | AX22: =IF(A22="","",IF(ISNUMBER(A22),MONTH(A22),IFERROR(VALUE(MID(A22,FIND(".",A22)+1,FIND(".",A22,FIND(".",A22)+1)-FIND(".",A22)-1)),""))) -> 6 | AY22: =IF(A22="","",IF(ISNUMBER(A22),YEAR(A22),IFERROR(VALUE(RIGHT(A22,4)),""))) -> 2026
A23: 46182 | C23: 3449523-9Y510206260135 | F23: MY0547078-9Z032705260052 | I23: MY0547099-9Z030406260060 | W23: MY0547078-9Y980206260102 | X23: MY0547078-9Z030306260039 | AU23: MY0547099-9Y980406260033 | AV23: 3449523-9Y980306260186 | AW23: 3449523-9Y510306260014 | AX23: =IF(A23="","",IF(ISNUMBER(A23),MONTH(A23),IFERROR(VALUE(MID(A23,FIND(".",A23)+1,FIND(".",A23,FIND(".",A23)+1)-FIND(".",A23)-1)),""))) -> 6 | AY23: =IF(A23="","",IF(ISNUMBER(A23),YEAR(A23),IFERROR(VALUE(RIGHT(A23,4)),""))) -> 2026
A24: 46182 | F24: 3449518-9Y520306260042 | I24: MY0547099-9Z220306260039 | W24: 3449518-9Y510206260169 | AU24: MY0547078-9Z030406260101 | AV24: 3449523-9Y510406260024 | AW24: 3449523-9Y510206260143 | AX24: =IF(A24="","",IF(ISNUMBER(A24),MONTH(A24),IFERROR(VALUE(MID(A24,FIND(".",A24)+1,FIND(".",A24,FIND(".",A24)+1)-FIND(".",A24)-1)),""))) -> 6 | AY24: =IF(A24="","",IF(ISNUMBER(A24),YEAR(A24),IFERROR(VALUE(RIGHT(A24,4)),""))) -> 2026
A25: 46182 | F25: MY0547078-9Y980406260073 | I25: MY0547099-8X820106260086 | AU25: MY0547099-9Y512805260079 | AV25: 3449523-9E380406260076 | AX25: =IF(A25="","",IF(ISNUMBER(A25),MONTH(A25),IFERROR(VALUE(MID(A25,FIND(".",A25)+1,FIND(".",A25,FIND(".",A25)+1)-FIND(".",A25)-1)),""))) -> 6 | AY25: =IF(A25="","",IF(ISNUMBER(A25),YEAR(A25),IFERROR(VALUE(RIGHT(A25,4)),""))) -> 2026
A26: 46183 | C26: 3449518-9Y980306260086 | F26: MY0547099-9Y740506260047 | I26: 3448362-9A842101260023 | W26: MY0547099-9Z030106260063 | X26: MY0547078-9Y510406260051 | AC26: MY0547078-8X820506260049 | AQ26: 3449518-9Y510506260128 | AU26: MY0547078-9Y510506260078 | AV26: MY0547099-9Z220406260101 | AW26: 3449523-9Y530406260130 | AX26: =IF(A26="","",IF(ISNUMBER(A26),MONTH(A26),IFERROR(VALUE(MID(A26,FIND(".",A26)+1,FIND(".",A26,FIND(".",A26)+1)-FIND(".",A26)-1)),""))) -> 6 | AY26: =IF(A26="","",IF(ISNUMBER(A26),YEAR(A26),IFERROR(VALUE(RIGHT(A26,4)),""))) -> 2026
A27: 46183 | F27: MY0547078-9Y520506260119 | AQ27: 3449518-9Y510506260126 | AU27: 3449518-9E380506260001 | AV27: 3449518-9Z040506260014 | AX27: =IF(A27="","",IF(ISNUMBER(A27),MONTH(A27),IFERROR(VALUE(MID(A27,FIND(".",A27)+1,FIND(".",A27,FIND(".",A27)+1)-FIND(".",A27)-1)),""))) -> 6 | AY27: =IF(A27="","",IF(ISNUMBER(A27),YEAR(A27),IFERROR(VALUE(RIGHT(A27,4)),""))) -> 2026
A28: 46183 | F28: 3449518-9Y510506260120 | AQ28: 3449518-9E380506260076 | AV28: MY0547099-9Y522805260131 | AX28: =IF(A28="","",IF(ISNUMBER(A28),MONTH(A28),IFERROR(VALUE(MID(A28,FIND(".",A28)+1,FIND(".",A28,FIND(".",A28)+1)-FIND(".",A28)-1)),""))) -> 6 | AY28: =IF(A28="","",IF(ISNUMBER(A28),YEAR(A28),IFERROR(VALUE(RIGHT(A28,4)),""))) -> 2026
A29: 46183 | F29: MY0547078-9Z030406260098 | AQ29: 3449518-9E380506260076 | AX29: =IF(A29="","",IF(ISNUMBER(A29),MONTH(A29),IFERROR(VALUE(MID(A29,FIND(".",A29)+1,FIND(".",A29,FIND(".",A29)+1)-FIND(".",A29)-1)),""))) -> 6 | AY29: =IF(A29="","",IF(ISNUMBER(A29),YEAR(A29),IFERROR(VALUE(RIGHT(A29,4)),""))) -> 2026
A30: 46183 | F30: 3449518-9E380406260134 | AX30: =IF(A30="","",IF(ISNUMBER(A30),MONTH(A30),IFERROR(VALUE(MID(A30,FIND(".",A30)+1,FIND(".",A30,FIND(".",A30)+1)-FIND(".",A30)-1)),""))) -> 6 | AY30: =IF(A30="","",IF(ISNUMBER(A30),YEAR(A30),IFERROR(VALUE(RIGHT(A30,4)),""))) -> 2026
A31: 46183 | F31: MY0547078-9Y510406260040 | AX31: =IF(A31="","",IF(ISNUMBER(A31),MONTH(A31),IFERROR(VALUE(MID(A31,FIND(".",A31)+1,FIND(".",A31,FIND(".",A31)+1)-FIND(".",A31)-1)),""))) -> 6 | AY31: =IF(A31="","",IF(ISNUMBER(A31),YEAR(A31),IFERROR(VALUE(RIGHT(A31,4)),""))) -> 2026
A32: 46184 | B32: MY0547078-9Y520706260008 | F32: MY0547078-8X820506260070 | I32: 3449523-9Y520106260100 | W32: 3449518-9E380506260105 | AU32: MY0547078-8X820506260051 | AX32: =IF(A32="","",IF(ISNUMBER(A32),MONTH(A32),IFERROR(VALUE(MID(A32,FIND(".",A32)+1,FIND(".",A32,FIND(".",A32)+1)-FIND(".",A32)-1)),""))) -> 6 | AY32: =IF(A32="","",IF(ISNUMBER(A32),YEAR(A32),IFERROR(VALUE(RIGHT(A32,4)),""))) -> 2026
A33: 46184 | F33: 3448362-8X820106260017 | AX33: =IF(A33="","",IF(ISNUMBER(A33),MONTH(A33),IFERROR(VALUE(MID(A33,FIND(".",A33)+1,FIND(".",A33,FIND(".",A33)+1)-FIND(".",A33)-1)),""))) -> 6 | AY33: =IF(A33="","",IF(ISNUMBER(A33),YEAR(A33),IFERROR(VALUE(RIGHT(A33,4)),""))) -> 2026
A34: 46184 | F34: 3449523-9E380406260058 | AX34: =IF(A34="","",IF(ISNUMBER(A34),MONTH(A34),IFERROR(VALUE(MID(A34,FIND(".",A34)+1,FIND(".",A34,FIND(".",A34)+1)-FIND(".",A34)-1)),""))) -> 6 | AY34: =IF(A34="","",IF(ISNUMBER(A34),YEAR(A34),IFERROR(VALUE(RIGHT(A34,4)),""))) -> 2026
A35: 46184 | F35: 3449523-9Z042805260059 | AX35: =IF(A35="","",IF(ISNUMBER(A35),MONTH(A35),IFERROR(VALUE(MID(A35,FIND(".",A35)+1,FIND(".",A35,FIND(".",A35)+1)-FIND(".",A35)-1)),""))) -> 6 | AY35: =IF(A35="","",IF(ISNUMBER(A35),YEAR(A35),IFERROR(VALUE(RIGHT(A35,4)),""))) -> 2026
A36: 46185 | E36: MY0547099-9E380806260008 | F36: MY0547099-8X820906260007 | X36: MY0547099-9Y510906260099 | AC36: 3448362-9Y520806260038 | AQ36: MY0547099-9E380806260016 | AX36: =IF(A36="","",IF(ISNUMBER(A36),MONTH(A36),IFERROR(VALUE(MID(A36,FIND(".",A36)+1,FIND(".",A36,FIND(".",A36)+1)-FIND(".",A36)-1)),""))) -> 6 | AY36: =IF(A36="","",IF(ISNUMBER(A36),YEAR(A36),IFERROR(VALUE(RIGHT(A36,4)),""))) -> 2026
A37: 46185 | X37: MY0547099-8X820906260081 | AX37: =IF(A37="","",IF(ISNUMBER(A37),MONTH(A37),IFERROR(VALUE(MID(A37,FIND(".",A37)+1,FIND(".",A37,FIND(".",A37)+1)-FIND(".",A37)-1)),""))) -> 6 | AY37: =IF(A37="","",IF(ISNUMBER(A37),YEAR(A37),IFERROR(VALUE(RIGHT(A37,4)),""))) -> 2026
A38: 46185 | X38: MY0547078-9Y741106260050 | AX38: =IF(A38="","",IF(ISNUMBER(A38),MONTH(A38),IFERROR(VALUE(MID(A38,FIND(".",A38)+1,FIND(".",A38,FIND(".",A38)+1)-FIND(".",A38)-1)),""))) -> 6 | AY38: =IF(A38="","",IF(ISNUMBER(A38),YEAR(A38),IFERROR(VALUE(RIGHT(A38,4)),""))) -> 2026
A39: 46188 | B39: MY0547078-9Y741106260036 | F39: MY0547078-9Y520906260104 | H39: MY0547099-9Y511006260040 | W39: MY0547099-9Y980906260048 | X39: 3449518-9Y980806260139 | AQ39: MY0547078-9Y520906260104 | AU39: MY0547078-9E380906260086 | AX39: =IF(A39="","",IF(ISNUMBER(A39),MONTH(A39),IFERROR(VALUE(MID(A39,FIND(".",A39)+1,FIND(".",A39,FIND(".",A39)+1)-FIND(".",A39)-1)),""))) -> 6 | AY39: =IF(A39="","",IF(ISNUMBER(A39),YEAR(A39),IFERROR(VALUE(RIGHT(A39,4)),""))) -> 2026 | AZ39: MY0547078-9Y742605260072
A40: 46188 | AQ40: MY0547078-9E381206260122 | AX40: =IF(A40="","",IF(ISNUMBER(A40),MONTH(A40),IFERROR(VALUE(MID(A40,FIND(".",A40)+1,FIND(".",A40,FIND(".",A40)+1)-FIND(".",A40)-1)),""))) -> 6 | AY40: =IF(A40="","",IF(ISNUMBER(A40),YEAR(A40),IFERROR(VALUE(RIGHT(A40,4)),""))) -> 2026
...

Sheet Sklad - na rework
A1: Datum | B1: FR HEAT | C1: FL HEAT | D1: FR | E1: FL | F1: RR | G1: RL
A2: 46072 | B2: MY0547099-9Z22 | C2: MY0547078-9Z03 | D2: 3448362-9Y74 | E2: 3448356-9Y53 | F2: 3449523-9E38 | G2: M3449618-9z22
A3: 46072 | B3: MY0547099-9Z22 | C3: MY0547078-9Z22 | D3: 3448362-9Y51 | E3: 3448356-9Y98 | F3: 3449523-9Y52 | G3: 3449518-9E38
A4: 46072 | B4: MY0547099-9Z04 | D4: MY0547099-9Y51 | E4: 3448356-9Y98 | G4: 3449518-9Y74
A5: 46072 | B5: MY0547099-9Y98 | D5: 3448362-9Y52 | E5: 3448356-9Y98 | G5: 3449518-9E38
A6: 46072 | D6: 3448362-9Y98 | E6: 3448356-9A84 | G6: 3449518-8X82
A7: 46072 | D7: 3448362-9E38 | E7: 3448356-9Y98 | G7: 3449518-8X82
A8: 46072 | E8: 3448356-9Y52
A9: 46072 | E9: 3448356-9Y52
A10: 46072 | E10: 3448356-9A84
A11: 46072 | E11: 3448356-9Y98
A12: 46072 | E12: 3448356-9A84
A13: 46072 | E13: 3448356-9Y51
A14: 46072 | E14: 3448356-9Y98
A15: 46072 | E15: 3448356-9E38
A16: 46073 | C16: MY0547099-9Y51 | D16: 3448362-9A84 | E16: 3448356-9E38 | F16: 3449523-9E38
A17: 46073 | C17: MY0547078-8X82 | D17: 3448362-9Y52 | E17: 3448356-9E38
A18: 46073 | C18: MY0547078-8X82 | D18: 3448362-9A84 | E18: 3448356-9Y74
A19: 46073 | C19: MY0547078-9Z22 | D19: 3448362-9A84 | E19: 3448356-9Y74
A20: 46073 | C20: MY0547078-8X82 | E20: 3448356-9Y52
A21: 46073 | C21: MY0547078-9E38 | E21: 3448356-9Y52
A22: 46073 | E22: 3448356-9Y52
A23: 46073 | E23: 3448356-9Y52
A24: 46073 | E24: 3448356-9Y74
A25: 46073 | E25: 3448356-9Y74
A26: 46073 | E26: 3448356-9Y74
A27: 46073 | E27: 3448356-9Y74
A28: 46073 | E28: 3448356-9Y74
A29: 46076 | B29: MY0547099-9Y74 | D29: 3448362-9Y51 | E29: 3448356-8X82 | G29: 3449518-9Y52
A30: 46076 | B30: MY0547099-9Y51 | G30: 3449518-9E38
A31: 46076 | B31: MY0547099-8X82
A32: 46076 | B32: MY0547099-9Y51
A33: 46076 | B33: MY0547099-9Z03
A34: 46076 | B34: MY0547099-9E38
A35: 46077 | B35: MY0547099-9E38 | F35: 3449523-9Y51 | G35: 3449518-9Y51
A36: 46077 | B36: MY0547099-9E38 | F36: 3449523-9Y52 | G36: 3449518-9Y52
A37: 46077 | B37: MY0547099-9Y98
A38: 46077 | B38: MY0547099-9E38
A39: 46077 | B39: MY0547099-9Y52
A40: 46077 | B40: MY0547099-9Y74
...

Sheet Pareto PREFIX
A1: Pareto graf – PREFIX
A2: Filtrovat dle měsíce: | B2: Vše | E2: ← vyberte měsíc nebo nechte 'Vše'
A3: Filtrovat dle roku: | B3: Vše | E3: ← vyberte rok nebo nechte 'Vše'
A6: Kód vady | B6: Popis vady | C6: Počet MC | D6: % podíl | E6: Kumulativní % | F6: Pořadí | I6: # | J6: Kód vady | K6: Popis vady | L6: Počet MC | M6: % podíl | N6: Kum. % | O6: Skóre
A7: SSP2 | B7: Spálený spacer | C7: =SUMPRODUCT(('Posouzení PREFIX'!B6:B205<>"")*('Posouzení PREFIX'!A6:A205<>"")*IF($B$2="Vše",1,'Posouzení PREFIX'!AW6:AW205=MATCH($B$2,{"Leden","Únor","Březen","Duben","Květen","Červen","Červenec","Srpen","Září","Říjen","Listopad","Prosinec"},0))*IF($B$3="Vše",1,'Posouzení PREFIX'!AX6:AX205=VALUE($B$3))) -> 31 | D7: =IF(C42>0,C7/C42,0) -> 0.057195572 | E7: =D7 -> 0.057195572 | F7: =IFERROR(RANK(C7,C$7:C$41,0),"") -> 6 | I7: 1 | J7: =IFERROR(INDEX(A7:A41,MATCH(LARGE(O7:O41,1),O7:O41,0)),"–") -> KRSK | K7: =IFERROR(INDEX(B7:B41,MATCH(LARGE(O7:O41,1),O7:O41,0)),"–") -> Kragujevac - skin defect | L7: =IFERROR(INDEX(C7:C41,MATCH(LARGE(O7:O41,1),O7:O41,0)),0) -> 167 | M7: =IFERROR(L7/C42,0) -> 0.30811808 | N7: =M7 -> 0.30811808 | O7: =C7+(1-ROW()*0.00001) -> 31.99993
A8: PMEP | B8: Mechanické poškození | C8: =SUMPRODUCT(('Posouzení PREFIX'!C6:C205<>"")*('Posouzení PREFIX'!A6:A205<>"")*IF($B$2="Vše",1,'Posouzení PREFIX'!AW6:AW205=MATCH($B$2,{"Leden","Únor","Březen","Duben","Květen","Červen","Červenec","Srpen","Září","Říjen","Listopad","Prosinec"},0))*IF($B$3="Vše",1,'Posouzení PREFIX'!AX6:AX205=VALUE($B$3))) -> 25 | D8: =IF(C42>0,C8/C42,0) -> 0.046125461 | E8: =SUM($D$7:D8) -> 0.10332103 | F8: =IFERROR(RANK(C8,C$7:C$41,0),"") -> 8 | I8: 2 | J8: =IFERROR(INDEX(A7:A41,MATCH(LARGE(O7:O41,2),O7:O41,0)),"–") -> KRSS | K8: =IFERROR(INDEX(B7:B41,MATCH(LARGE(O7:O41,2),O7:O41,0)),"–") -> Kragujevac - short skin | L8: =IFERROR(INDEX(C7:C41,MATCH(LARGE(O7:O41,2),O7:O41,0)),0) -> 112 | M8: =IFERROR(L8/C42,0) -> 0.20664207 | N8: =SUM($M$7:M8) -> 0.51476015 | O8: =C8+(1-ROW()*0.00001) -> 25.99992
A9: OHN2 | B9: Odřená hrana | C9: =SUMPRODUCT(('Posouzení PREFIX'!D6:D205<>"")*('Posouzení PREFIX'!A6:A205<>"")*IF($B$2="Vše",1,'Posouzení PREFIX'!AW6:AW205=MATCH($B$2,{"Leden","Únor","Březen","Duben","Květen","Červen","Červenec","Srpen","Září","Říjen","Listopad","Prosinec"},0))*IF($B$3="Vše",1,'Posouzení PREFIX'!AX6:AX205=VALUE($B$3))) -> 0 | D9: =IF(C42>0,C9/C42,0) -> 0 | E9: =SUM($D$7:D9) -> 0.10332103 | F9: =IFERROR(RANK(C9,C$7:C$41,0),"") -> 21 | I9: 3 | J9: =IFERROR(INDEX(A7:A41,MATCH(LARGE(O7:O41,3),O7:O41,0)),"–") -> SPF | K9: =IFERROR(INDEX(B7:B41,MATCH(LARGE(O7:O41,3),O7:O41,0)),"–") -> Špatný prefix | L9: =IFERROR(INDEX(C7:C41,MATCH(LARGE(O7:O41,3),O7:O41,0)),0) -> 70 | M9: =IFERROR(L9/C42,0) -> 0.12915129 | N9: =SUM($M$7:M9) -> 0.64391144 | O9: =C9+(1-ROW()*0.00001) -> 0.99991
A10: PSKU | B10: Spálená kůže | C10: =SUMPRODUCT(('Posouzení PREFIX'!E6:E205<>"")*('Posouzení PREFIX'!A6:A205<>"")*IF($B$2="Vše",1,'Posouzení PREFIX'!AW6:AW205=MATCH($B$2,{"Leden","Únor","Březen","Duben","Květen","Červen","Červenec","Srpen","Září","Říjen","Listopad","Prosinec"},0))*IF($B$3="Vše",1,'Posouzení PREFIX'!AX6:AX205=VALUE($B$3))) -> 6 | D10: =IF(C42>0,C10/C42,0) -> 0.011070111 | E10: =SUM($D$7:D10) -> 0.11439114 | F10: =IFERROR(RANK(C10,C$7:C$41,0),"") -> 11 | I10: 4 | J10: =IFERROR(INDEX(A7:A41,MATCH(LARGE(O7:O41,4),O7:O41,0)),"–") -> KRSW | K10: =IFERROR(INDEX(B7:B41,MATCH(LARGE(O7:O41,4),O7:O41,0)),"–") -> Kragujevac - sewing | L10: =IFERROR(INDEX(C7:C41,MATCH(LARGE(O7:O41,4),O7:O41,0)),0) -> 36 | M10: =IFERROR(L10/C42,0) -> 0.066420664 | N10: =SUM($M$7:M10) -> 0.7103321 | O10: =C10+(1-ROW()*0.00001) -> 6.9999
A11: PDSP | B11: Deformovaný spacer | C11: =SUMPRODUCT(('Posouzení PREFIX'!F6:F205<>"")*('Posouzení PREFIX'!A6:A205<>"")*IF($B$2="Vše",1,'Posouzení PREFIX'!AW6:AW205=MATCH($B$2,{"Leden","Únor","Březen","Duben","Květen","Červen","Červenec","Srpen","Září","Říjen","Listopad","Prosinec"},0))*IF($B$3="Vše",1,'Posouzení PREFIX'!AX6:AX205=VALUE($B$3))) -> 28 | D11: =IF(C42>0,C11/C42,0) -> 0.051660517 | E11: =SUM($D$7:D11) -> 0.16605166 | F11: =IFERROR(RANK(C11,C$7:C$41,0),"") -> 7 | I11: 5 | J11: =IFERROR(INDEX(A7:A41,MATCH(LARGE(O7:O41,5),O7:O41,0)),"–") -> NRW | K11: =IFERROR(INDEX(B7:B41,MATCH(LARGE(O7:O41,5),O7:O41,0)),"–") -> NOK rework | L11: =IFERROR(INDEX(C7:C41,MATCH(LARGE(O7:O41,5),O7:O41,0)),0) -> 33 | M11: =IFERROR(L11/C42,0) -> 0.060885609 | N11: =SUM($M$7:M11) -> 0.77121771 | O11: =C11+(1-ROW()*0.00001) -> 28.99989
A12: PLPK | B12: Lepidlo pod kůží | C12: =SUMPRODUCT(('Posouzení PREFIX'!G6:G205<>"")*('Posouzení PREFIX'!A6:A205<>"")*IF($B$2="Vše",1,'Posouzení PREFIX'!AW6:AW205=MATCH($B$2,{"Leden","Únor","Březen","Duben","Květen","Červen","Červenec","Srpen","Září","Říjen","Listopad","Prosinec"},0))*IF($B$3="Vše",1,'Posouzení PREFIX'!AX6:AX205=VALUE($B$3))) -> 5 | D12: =IF(C42>0,C12/C42,0) -> 0.0092250923 | E12: =SUM($D$7:D12) -> 0.17527675 | F12: =IFERROR(RANK(C12,C$7:C$41,0),"") -> 12 | I12: 6 | J12: =IFERROR(INDEX(A7:A41,MATCH(LARGE(O7:O41,6),O7:O41,0)),"–") -> SSP2 | K12: =IFERROR(INDEX(B7:B41,MATCH(LARGE(O7:O41,6),O7:O41,0)),"–") -> Spálený spacer | L12: =IFERROR(INDEX(C7:C41,MATCH(LARGE(O7:O41,6),O7:O41,0)),0) -> 31 | M12: =IFERROR(L12/C42,0) -> 0.057195572 | N12: =SUM($M$7:M12) -> 0.82841328 | O12: =C12+(1-ROW()*0.00001) -> 5.99988
A13: PSNA | B13: Špatný nástřih | C13: =SUMPRODUCT(('Posouzení PREFIX'!H6:H205<>"")*('Posouzení PREFIX'!A6:A205<>"")*IF($B$2="Vše",1,'Posouzení PREFIX'!AW6:AW205=MATCH($B$2,{"Leden","Únor","Březen","Duben","Květen","Červen","Červenec","Srpen","Září","Říjen","Listopad","Prosinec"},0))*IF($B$3="Vše",1,'Posouzení PREFIX'!AX6:AX205=VALUE($B$3))) -> 9 | D13: =IF(C42>0,C13/C42,0) -> 0.016605166 | E13: =SUM($D$7:D13) -> 0.19188192 | F13: =IFERROR(RANK(C13,C$7:C$41,0),"") -> 9 | I13: 7 | J13: =IFERROR(INDEX(A7:A41,MATCH(LARGE(O7:O41,7),O7:O41,0)),"–") -> PDSP | K13: =IFERROR(INDEX(B7:B41,MATCH(LARGE(O7:O41,7),O7:O41,0)),"–") -> Deformovaný spacer | L13: =IFERROR(INDEX(C7:C41,MATCH(LARGE(O7:O41,7),O7:O41,0)),0) -> 28 | M13: =IFERROR(L13/C42,0) -> 0.051660517 | N13: =SUM($M$7:M13) -> 0.8800738 | O13: =C13+(1-ROW()*0.00001) -> 9.99987
A14: LEP | B14: Špatně nanesené lepidlo | C14: =SUMPRODUCT(('Posouzení PREFIX'!I6:I205<>"")*('Posouzení PREFIX'!A6:A205<>"")*IF($B$2="Vše",1,'Posouzení PREFIX'!AW6:AW205=MATCH($B$2,{"Leden","Únor","Březen","Duben","Květen","Červen","Červenec","Srpen","Září","Říjen","Listopad","Prosinec"},0))*IF($B$3="Vše",1,'Posouzení PREFIX'!AX6:AX205=VALUE($B$3))) -> 2 | D14: =IF(C42>0,C14/C42,0) -> 0.0036900369 | E14: =SUM($D$7:D14) -> 0.19557196 | F14: =IFERROR(RANK(C14,C$7:C$41,0),"") -> 13 | I14: 8 | J14: =IFERROR(INDEX(A7:A41,MATCH(LARGE(O7:O41,8),O7:O41,0)),"–") -> PMEP | K14: =IFERROR(INDEX(B7:B41,MATCH(LARGE(O7:O41,8),O7:O41,0)),"–") -> Mechanické poškození | L14: =IFERROR(INDEX(C7:C41,MATCH(LARGE(O7:O41,8),O7:O41,0)),0) -> 25 | M14: =IFERROR(L14/C42,0) -> 0.046125461 | N14: =SUM($M$7:M14) -> 0.92619926 | O14: =C14+(1-ROW()*0.00001) -> 2.99986
A15: PVZD | B15: Vzduch | C15: =SUMPRODUCT(('Posouzení PREFIX'!J6:J205<>"")*('Posouzení PREFIX'!A6:A205<>"")*IF($B$2="Vše",1,'Posouzení PREFIX'!AW6:AW205=MATCH($B$2,{"Leden","Únor","Březen","Duben","Květen","Červen","Červenec","Srpen","Září","Říjen","Listopad","Prosinec"},0))*IF($B$3="Vše",1,'Posouzení PREFIX'!AX6:AX205=VALUE($B$3))) -> 2 | D15: =IF(C42>0,C15/C42,0) -> 0.0036900369 | E15: =SUM($D$7:D15) -> 0.19926199 | F15: =IFERROR(RANK(C15,C$7:C$41,0),"") -> 13 | I15: 9 | J15: =IFERROR(INDEX(A7:A41,MATCH(LARGE(O7:O41,9),O7:O41,0)),"–") -> PSNA | K15: =IFERROR(INDEX(B7:B41,MATCH(LARGE(O7:O41,9),O7:O41,0)),"–") -> Špatný nástřih | L15: =IFERROR(INDEX(C7:C41,MATCH(LARGE(O7:O41,9),O7:O41,0)),0) -> 9 | M15: =IFERROR(L15/C42,0) -> 0.016605166 | N15: =SUM($M$7:M15) -> 0.94280443 | O15: =C15+(1-ROW()*0.00001) -> 2.99985
A16: PSMK | B16: Šev mimo kanál | C16: =SUMPRODUCT(('Posouzení PREFIX'!K6:K205<>"")*('Posouzení PREFIX'!A6:A205<>"")*IF($B$2="Vše",1,'Posouzení PREFIX'!AW6:AW205=MATCH($B$2,{"Leden","Únor","Březen","Duben","Květen","Červen","Červenec","Srpen","Září","Říjen","Listopad","Prosinec"},0))*IF($B$3="Vše",1,'Posouzení PREFIX'!AX6:AX205=VALUE($B$3))) -> 0 | D16: =IF(C42>0,C16/C42,0) -> 0 | E16: =SUM($D$7:D16) -> 0.19926199 | F16: =IFERROR(RANK(C16,C$7:C$41,0),"") -> 21 | I16: 10 | J16: =IFERROR(INDEX(A7:A41,MATCH(LARGE(O7:O41,10),O7:O41,0)),"–") -> PDEP | K16: =IFERROR(INDEX(B7:B41,MATCH(LARGE(O7:O41,10),O7:O41,0)),"–") -> Deformace plastu | L16: =IFERROR(INDEX(C7:C41,MATCH(LARGE(O7:O41,10),O7:O41,0)),0) -> 8 | M16: =IFERROR(L16/C42,0) -> 0.014760148 | N16: =SUM($M$7:M16) -> 0.95756458 | O16: =C16+(1-ROW()*0.00001) -> 0.99984
A17: ZVR | B17: Zvrásnění povrchu | C17: =SUMPRODUCT(('Posouzení PREFIX'!L6:L205<>"")*('Posouzení PREFIX'!A6:A205<>"")*IF($B$2="Vše",1,'Posouzení PREFIX'!AW6:AW205=MATCH($B$2,{"Leden","Únor","Březen","Duben","Květen","Červen","Červenec","Srpen","Září","Říjen","Listopad","Prosinec"},0))*IF($B$3="Vše",1,'Posouzení PREFIX'!AX6:AX205=VALUE($B$3))) -> 0 | D17: =IF(C42>0,C17/C42,0) -> 0 | E17: =SUM($D$7:D17) -> 0.19926199 | F17: =IFERROR(RANK(C17,C$7:C$41,0),"") -> 21 | I17: 11 | J17: =IFERROR(INDEX(A7:A41,MATCH(LARGE(O7:O41,11),O7:O41,0)),"–") -> PSKU | K17: =IFERROR(INDEX(B7:B41,MATCH(LARGE(O7:O41,11),O7:O41,0)),"–") -> Spálená kůže | L17: =IFERROR(INDEX(C7:C41,MATCH(LARGE(O7:O41,11),O7:O41,0)),0) -> 6 | M17: =IFERROR(L17/C42,0) -> 0.011070111 | N17: =SUM($M$7:M17) -> 0.96863469 | O17: =C17+(1-ROW()*0.00001) -> 0.99983
A18: LAB | B18: Testy laboratoř | C18: =SUMPRODUCT(('Posouzení PREFIX'!M6:M205<>"")*('Posouzení PREFIX'!A6:A205<>"")*IF($B$2="Vše",1,'Posouzení PREFIX'!AW6:AW205=MATCH($B$2,{"Leden","Únor","Březen","Duben","Květen","Červen","Červenec","Srpen","Září","Říjen","Listopad","Prosinec"},0))*IF($B$3="Vše",1,'Posouzení PREFIX'!AX6:AX205=VALUE($B$3))) -> 0 | D18: =IF(C42>0,C18/C42,0) -> 0 | E18: =SUM($D$7:D18) -> 0.19926199 | F18: =IFERROR(RANK(C18,C$7:C$41,0),"") -> 21 | I18: 12 | J18: =IFERROR(INDEX(A7:A41,MATCH(LARGE(O7:O41,12),O7:O41,0)),"–") -> PLPK | K18: =IFERROR(INDEX(B7:B41,MATCH(LARGE(O7:O41,12),O7:O41,0)),"–") -> Lepidlo pod kůží | L18: =IFERROR(INDEX(C7:C41,MATCH(LARGE(O7:O41,12),O7:O41,0)),0) -> 5 | M18: =IFERROR(L18/C42,0) -> 0.0092250923 | N18: =SUM($M$7:M18) -> 0.97785978 | O18: =C18+(1-ROW()*0.00001) -> 0.99982
A19: PKOL | B19: Kontaminace lepidlem | C19: =SUMPRODUCT(('Posouzení PREFIX'!N6:N205<>"")*('Posouzení PREFIX'!A6:A205<>"")*IF($B$2="Vše",1,'Posouzení PREFIX'!AW6:AW205=MATCH($B$2,{"Leden","Únor","Březen","Duben","Květen","Červen","Červenec","Srpen","Září","Říjen","Listopad","Prosinec"},0))*IF($B$3="Vše",1,'Posouzení PREFIX'!AX6:AX205=VALUE($B$3))) -> 0 | D19: =IF(C42>0,C19/C42,0) -> 0 | E19: =SUM($D$7:D19) -> 0.19926199 | F19: =IFERROR(RANK(C19,C$7:C$41,0),"") -> 21 | I19: 13 | J19: =IFERROR(INDEX(A7:A41,MATCH(LARGE(O7:O41,13),O7:O41,0)),"–") -> LEP | K19: =IFERROR(INDEX(B7:B41,MATCH(LARGE(O7:O41,13),O7:O41,0)),"–") -> Špatně nanesené lepidlo | L19: =IFERROR(INDEX(C7:C41,MATCH(LARGE(O7:O41,13),O7:O41,0)),0) -> 2 | M19: =IFERROR(L19/C42,0) -> 0.0036900369 | N19: =SUM($M$7:M19) -> 0.98154982 | O19: =C19+(1-ROW()*0.00001) -> 0.99981
A20: PELC | B20: Expirované lepidlo na MC | C20: =SUMPRODUCT(('Posouzení PREFIX'!O6:O205<>"")*('Posouzení PREFIX'!A6:A205<>"")*IF($B$2="Vše",1,'Posouzení PREFIX'!AW6:AW205=MATCH($B$2,{"Leden","Únor","Březen","Duben","Květen","Červen","Červenec","Srpen","Září","Říjen","Listopad","Prosinec"},0))*IF($B$3="Vše",1,'Posouzení PREFIX'!AX6:AX205=VALUE($B$3))) -> 2 | D20: =IF(C42>0,C20/C42,0) -> 0.0036900369 | E20: =SUM($D$7:D20) -> 0.20295203 | F20: =IFERROR(RANK(C20,C$7:C$41,0),"") -> 13 | I20: 14 | J20: =IFERROR(INDEX(A7:A41,MATCH(LARGE(O7:O41,14),O7:O41,0)),"–") -> PVZD | K20: =IFERROR(INDEX(B7:B41,MATCH(LARGE(O7:O41,14),O7:O41,0)),"–") -> Vzduch | L20: =IFERROR(INDEX(C7:C41,MATCH(LARGE(O7:O41,14),O7:O41,0)),0) -> 2 | M20: =IFERROR(L20/C42,0) -> 0.0036900369 | N20: =SUM($M$7:M20) -> 0.98523985 | O20: =C20+(1-ROW()*0.00001) -> 2.9998
A21: PDEP | B21: Deformace plastu | C21: =SUMPRODUCT(('Posouzení PREFIX'!P6:P205<>"")*('Posouzení PREFIX'!A6:A205<>"")*IF($B$2="Vše",1,'Posouzení PREFIX'!AW6:AW205=MATCH($B$2,{"Leden","Únor","Březen","Duben","Květen","Červen","Červenec","Srpen","Září","Říjen","Listopad","Prosinec"},0))*IF($B$3="Vše",1,'Posouzení PREFIX'!AX6:AX205=VALUE($B$3))) -> 8 | D21: =IF(C42>0,C21/C42,0) -> 0.014760148 | E21: =SUM($D$7:D21) -> 0.21771218 | F21: =IFERROR(RANK(C21,C$7:C$41,0),"") -> 10 | I21: 15 | J21: =IFERROR(INDEX(A7:A41,MATCH(LARGE(O7:O41,15),O7:O41,0)),"–") -> PELC | K21: =IFERROR(INDEX(B7:B41,MATCH(LARGE(O7:O41,15),O7:O41,0)),"–") -> Expirované lepidlo na MC | L21: =IFERROR(INDEX(C7:C41,MATCH(LARGE(O7:O41,15),O7:O41,0)),0) -> 2 | M21: =IFERROR(L21/C42,0) -> 0.0036900369 | N21: =SUM($M$7:M21) -> 0.98892989 | O21: =C21+(1-ROW()*0.00001) -> 8.99979
A22: PNHE | B22: Nefunkční heating | C22: =SUMPRODUCT(('Posouzení PREFIX'!Q6:Q205<>"")*('Posouzení PREFIX'!A6:A205<>"")*IF($B$2="Vše",1,'Posouzení PREFIX'!AW6:AW205=MATCH($B$2,{"Leden","Únor","Březen","Duben","Květen","Červen","Červenec","Srpen","Září","Říjen","Listopad","Prosinec"},0))*IF($B$3="Vše",1,'Posouzení PREFIX'!AX6:AX205=VALUE($B$3))) -> 0 | D22: =IF(C42>0,C22/C42,0) -> 0 | E22: =SUM($D$7:D22) -> 0.21771218 | F22: =IFERROR(RANK(C22,C$7:C$41,0),"") -> 21 | I22: 16 | J22: =IFERROR(INDEX(A7:A41,MATCH(LARGE(O7:O41,16),O7:O41,0)),"–") -> OTL | K22: =IFERROR(INDEX(B7:B41,MATCH(LARGE(O7:O41,16),O7:O41,0)),"–") -> Otlak | L22: =IFERROR(INDEX(C7:C41,MATCH(LARGE(O7:O41,16),O7:O41,0)),0) -> 2 | M22: =IFERROR(L22/C42,0) -> 0.0036900369 | N22: =SUM($M$7:M22) -> 0.99261993 | O22: =C22+(1-ROW()*0.00001) -> 0.99978
A23: OTL | B23: Otlak | C23: =SUMPRODUCT(('Posouzení PREFIX'!W6:W205<>"")*('Posouzení PREFIX'!A6:A205<>"")*IF($B$2="Vše",1,'Posouzení PREFIX'!AW6:AW205=MATCH($B$2,{"Leden","Únor","Březen","Duben","Květen","Červen","Červenec","Srpen","Září","Říjen","Listopad","Prosinec"},0))*IF($B$3="Vše",1,'Posouzení PREFIX'!AX6:AX205=VALUE($B$3))) -> 2 | D23: =IF(C42>0,C23/C42,0) -> 0.0036900369 | E23: =SUM($D$7:D23) -> 0.22140221 | F23: =IFERROR(RANK(C23,C$7:C$41,0),"") -> 13 | I23: 17 | J23: =IFERROR(INDEX(A7:A41,MATCH(LARGE(O7:O41,17),O7:O41,0)),"–") -> ZHN | K23: =IFERROR(INDEX(B7:B41,MATCH(LARGE(O7:O41,17),O7:O41,0)),"–") -> Zahranění NOK | L23: =IFERROR(INDEX(C7:C41,MATCH(LARGE(O7:O41,17),O7:O41,0)),0) -> 1 | M23: =IFERROR(L23/C42,0) -> 0.0018450185 | N23: =SUM($M$7:M23) -> 0.99446494 | O23: =C23+(1-ROW()*0.00001) -> 2.99977
A24: NRW | B24: NOK rework | C24: =SUMPRODUCT(('Posouzení PREFIX'!Y6:Y205<>"")*('Posouzení PREFIX'!A6:A205<>"")*IF($B$2="Vše",1,'Posouzení PREFIX'!AW6:AW205=MATCH($B$2,{"Leden","Únor","Březen","Duben","Květen","Červen","Červenec","Srpen","Září","Říjen","Listopad","Prosinec"},0))*IF($B$3="Vše",1,'Posouzení PREFIX'!AX6:AX205=VALUE($B$3))) -> 33 | D24: =IF(C42>0,C24/C42,0) -> 0.060885609 | E24: =SUM($D$7:D24) -> 0.28228782 | F24: =IFERROR(RANK(C24,C$7:C$41,0),"") -> 5 | I24: 18 | J24: =IFERROR(INDEX(A7:A41,MATCH(LARGE(O7:O41,18),O7:O41,0)),"–") -> PSZA | K24: =IFERROR(INDEX(B7:B41,MATCH(LARGE(O7:O41,18),O7:O41,0)),"–") -> Špatný zaříznutí | L24: =IFERROR(INDEX(C7:C41,MATCH(LARGE(O7:O41,18),O7:O41,0)),0) -> 1 | M24: =IFERROR(L24/C42,0) -> 0.0018450185 | N24: =SUM($M$7:M24) -> 0.99630996 | O24: =C24+(1-ROW()*0.00001) -> 33.99976
A25: SPF | B25: Špatný prefix | C25: =SUMPRODUCT(('Posouzení PREFIX'!Z6:Z205<>"")*('Posouzení PREFIX'!A6:A205<>"")*IF($B$2="Vše",1,'Posouzení PREFIX'!AW6:AW205=MATCH($B$2,{"Leden","Únor","Březen","Duben","Květen","Červen","Červenec","Srpen","Září","Říjen","Listopad","Prosinec"},0))*IF($B$3="Vše",1,'Posouzení PREFIX'!AX6:AX205=VALUE($B$3))) -> 70 | D25: =IF(C42>0,C25/C42,0) -> 0.12915129 | E25: =SUM($D$7:D25) -> 0.41143911 | F25: =IFERROR(RANK(C25,C$7:C$41,0),"") -> 3 | I25: 19 | J25: =IFERROR(INDEX(A7:A41,MATCH(LARGE(O7:O41,19),O7:O41,0)),"–") -> PSPC | K25: =IFERROR(INDEX(B7:B41,MATCH(LARGE(O7:O41,19),O7:O41,0)),"–") -> Špatný spacer | L25: =IFERROR(INDEX(C7:C41,MATCH(LARGE(O7:O41,19),O7:O41,0)),0) -> 1 | M25: =IFERROR(L25/C42,0) -> 0.0018450185 | N25: =SUM($M$7:M25) -> 0.99815498 | O25: =C25+(1-ROW()*0.00001) -> 70.99975
A26: DEL | B26: Delaminace (hrany) | C26: =SUMPRODUCT(('Posouzení PREFIX'!AA6:AA205<>"")*('Posouzení PREFIX'!A6:A205<>"")*IF($B$2="Vše",1,'Posouzení PREFIX'!AW6:AW205=MATCH($B$2,{"Leden","Únor","Březen","Duben","Květen","Červen","Červenec","Srpen","Září","Říjen","Listopad","Prosinec"},0))*IF($B$3="Vše",1,'Posouzení PREFIX'!AX6:AX205=VALUE($B$3))) -> 0 | D26: =IF(C42>0,C26/C42,0) -> 0 | E26: =SUM($D$7:D26) -> 0.41143911 | F26: =IFERROR(RANK(C26,C$7:C$41,0),"") -> 21 | I26: 20 | J26: =IFERROR(INDEX(A7:A41,MATCH(LARGE(O7:O41,20),O7:O41,0)),"–") -> PSGL | K26: =IFERROR(INDEX(B7:B41,MATCH(LARGE(O7:O41,20),O7:O41,0)),"–") -> Špatná gramáž lepidla | L26: =IFERROR(INDEX(C7:C41,MATCH(LARGE(O7:O41,20),O7:O41,0)),0) -> 1 | M26: =IFERROR(L26/C42,0) -> 0.0018450185 | N26: =SUM($M$7:M26) -> 1 | O26: =C26+(1-ROW()*0.00001) -> 0.99974
A27: PDEL | B27: Delaminace (plochy) | C27: =SUMPRODUCT(('Posouzení PREFIX'!AB6:AB205<>"")*('Posouzení PREFIX'!A6:A205<>"")*IF($B$2="Vše",1,'Posouzení PREFIX'!AW6:AW205=MATCH($B$2,{"Leden","Únor","Březen","Duben","Květen","Červen","Červenec","Srpen","Září","Říjen","Listopad","Prosinec"},0))*IF($B$3="Vše",1,'Posouzení PREFIX'!AX6:AX205=VALUE($B$3))) -> 0 | D27: =IF(C42>0,C27/C42,0) -> 0 | E27: =SUM($D$7:D27) -> 0.41143911 | F27: =IFERROR(RANK(C27,C$7:C$41,0),"") -> 21 | I27: 21 | J27: =IFERROR(INDEX(A7:A41,MATCH(LARGE(O7:O41,21),O7:O41,0)),"–") -> OHN2 | K27: =IFERROR(INDEX(B7:B41,MATCH(LARGE(O7:O41,21),O7:O41,0)),"–") -> Odřená hrana | L27: =IFERROR(INDEX(C7:C41,MATCH(LARGE(O7:O41,21),O7:O41,0)),0) -> 0 | M27: =IFERROR(L27/C42,0) -> 0 | N27: =SUM($M$7:M27) -> 1 | O27: =C27+(1-ROW()*0.00001) -> 0.99973
A28: ZHN | B28: Zahranění NOK | C28: =SUMPRODUCT(('Posouzení PREFIX'!AC6:AC205<>"")*('Posouzení PREFIX'!A6:A205<>"")*IF($B$2="Vše",1,'Posouzení PREFIX'!AW6:AW205=MATCH($B$2,{"Leden","Únor","Březen","Duben","Květen","Červen","Červenec","Srpen","Září","Říjen","Listopad","Prosinec"},0))*IF($B$3="Vše",1,'Posouzení PREFIX'!AX6:AX205=VALUE($B$3))) -> 1 | D28: =IF(C42>0,C28/C42,0) -> 0.0018450185 | E28: =SUM($D$7:D28) -> 0.41328413 | F28: =IFERROR(RANK(C28,C$7:C$41,0),"") -> 17 | I28: 22 | J28: =IFERROR(INDEX(A7:A41,MATCH(LARGE(O7:O41,22),O7:O41,0)),"–") -> PSMK | K28: =IFERROR(INDEX(B7:B41,MATCH(LARGE(O7:O41,22),O7:O41,0)),"–") -> Šev mimo kanál | L28: =IFERROR(INDEX(C7:C41,MATCH(LARGE(O7:O41,22),O7:O41,0)),0) -> 0 | M28: =IFERROR(L28/C42,0) -> 0 | N28: =SUM($M$7:M28) -> 1 | O28: =C28+(1-ROW()*0.00001) -> 1.99972
A29: PSZA | B29: Špatný zaříznutí | C29: =SUMPRODUCT(('Posouzení PREFIX'!AD6:AD205<>"")*('Posouzení PREFIX'!A6:A205<>"")*IF($B$2="Vše",1,'Posouzení PREFIX'!AW6:AW205=MATCH($B$2,{"Leden","Únor","Březen","Duben","Květen","Červen","Červenec","Srpen","Září","Říjen","Listopad","Prosinec"},0))*IF($B$3="Vše",1,'Posouzení PREFIX'!AX6:AX205=VALUE($B$3))) -> 1 | D29: =IF(C42>0,C29/C42,0) -> 0.0018450185 | E29: =SUM($D$7:D29) -> 0.41512915 | F29: =IFERROR(RANK(C29,C$7:C$41,0),"") -> 17 | I29: 23 | J29: =IFERROR(INDEX(A7:A41,MATCH(LARGE(O7:O41,23),O7:O41,0)),"–") -> ZVR | K29: =IFERROR(INDEX(B7:B41,MATCH(LARGE(O7:O41,23),O7:O41,0)),"–") -> Zvrásnění povrchu | L29: =IFERROR(INDEX(C7:C41,MATCH(LARGE(O7:O41,23),O7:O41,0)),0) -> 0 | M29: =IFERROR(L29/C42,0) -> 0 | N29: =SUM($M$7:M29) -> 1 | O29: =C29+(1-ROW()*0.00001) -> 1.99971
A30: ZNA | B30: Znečištění od ASQ | C30: =SUMPRODUCT(('Posouzení PREFIX'!AE6:AE205<>"")*('Posouzení PREFIX'!A6:A205<>"")*IF($B$2="Vše",1,'Posouzení PREFIX'!AW6:AW205=MATCH($B$2,{"Leden","Únor","Březen","Duben","Květen","Červen","Červenec","Srpen","Září","Říjen","Listopad","Prosinec"},0))*IF($B$3="Vše",1,'Posouzení PREFIX'!AX6:AX205=VALUE($B$3))) -> 0 | D30: =IF(C42>0,C30/C42,0) -> 0 | E30: =SUM($D$7:D30) -> 0.41512915 | F30: =IFERROR(RANK(C30,C$7:C$41,0),"") -> 21 | I30: 24 | J30: =IFERROR(INDEX(A7:A41,MATCH(LARGE(O7:O41,24),O7:O41,0)),"–") -> LAB | K30: =IFERROR(INDEX(B7:B41,MATCH(LARGE(O7:O41,24),O7:O41,0)),"–") -> Testy laboratoř | L30: =IFERROR(INDEX(C7:C41,MATCH(LARGE(O7:O41,24),O7:O41,0)),0) -> 0 | M30: =IFERROR(L30/C42,0) -> 0 | N30: =SUM($M$7:M30) -> 1 | O30: =C30+(1-ROW()*0.00001) -> 0.9997
A31: FLEK | B31: Flek | C31: =SUMPRODUCT(('Posouzení PREFIX'!AG6:AG205<>"")*('Posouzení PREFIX'!A6:A205<>"")*IF($B$2="Vše",1,'Posouzení PREFIX'!AW6:AW205=MATCH($B$2,{"Leden","Únor","Březen","Duben","Květen","Červen","Červenec","Srpen","Září","Říjen","Listopad","Prosinec"},0))*IF($B$3="Vše",1,'Posouzení PREFIX'!AX6:AX205=VALUE($B$3))) -> 0 | D31: =IF(C42>0,C31/C42,0) -> 0 | E31: =SUM($D$7:D31) -> 0.41512915 | F31: =IFERROR(RANK(C31,C$7:C$41,0),"") -> 21 | I31: 25 | J31: =IFERROR(INDEX(A7:A41,MATCH(LARGE(O7:O41,25),O7:O41,0)),"–") -> PKOL | K31: =IFERROR(INDEX(B7:B41,MATCH(LARGE(O7:O41,25),O7:O41,0)),"–") -> Kontaminace lepidlem | L31: =IFERROR(INDEX(C7:C41,MATCH(LARGE(O7:O41,25),O7:O41,0)),0) -> 0 | M31: =IFERROR(L31/C42,0) -> 0 | N31: =SUM($M$7:M31) -> 1 | O31: =C31+(1-ROW()*0.00001) -> 0.99969
A32: PSPC | B32: Špatný spacer | C32: =SUMPRODUCT(('Posouzení PREFIX'!AI6:AI205<>"")*('Posouzení PREFIX'!A6:A205<>"")*IF($B$2="Vše",1,'Posouzení PREFIX'!AW6:AW205=MATCH($B$2,{"Leden","Únor","Březen","Duben","Květen","Červen","Červenec","Srpen","Září","Říjen","Listopad","Prosinec"},0))*IF($B$3="Vše",1,'Posouzení PREFIX'!AX6:AX205=VALUE($B$3))) -> 1 | D32: =IF(C42>0,C32/C42,0) -> 0.0018450185 | E32: =SUM($D$7:D32) -> 0.41697417 | F32: =IFERROR(RANK(C32,C$7:C$41,0),"") -> 17 | I32: 26 | J32: =IFERROR(INDEX(A7:A41,MATCH(LARGE(O7:O41,26),O7:O41,0)),"–") -> PNHE | K32: =IFERROR(INDEX(B7:B41,MATCH(LARGE(O7:O41,26),O7:O41,0)),"–") -> Nefunkční heating | L32: =IFERROR(INDEX(C7:C41,MATCH(LARGE(O7:O41,26),O7:O41,0)),0) -> 0 | M32: =IFERROR(L32/C42,0) -> 0 | N32: =SUM($M$7:M32) -> 1 | O32: =C32+(1-ROW()*0.00001) -> 1.99968
A33: PSKZ | B33: Špatná kůže | C33: =SUMPRODUCT(('Posouzení PREFIX'!AJ6:AJ205<>"")*('Posouzení PREFIX'!A6:A205<>"")*IF($B$2="Vše",1,'Posouzení PREFIX'!AW6:AW205=MATCH($B$2,{"Leden","Únor","Březen","Duben","Květen","Červen","Červenec","Srpen","Září","Říjen","Listopad","Prosinec"},0))*IF($B$3="Vše",1,'Posouzení PREFIX'!AX6:AX205=VALUE($B$3))) -> 0 | D33: =IF(C42>0,C33/C42,0) -> 0 | E33: =SUM($D$7:D33) -> 0.41697417 | F33: =IFERROR(RANK(C33,C$7:C$41,0),"") -> 21 | I33: 27 | J33: =IFERROR(INDEX(A7:A41,MATCH(LARGE(O7:O41,27),O7:O41,0)),"–") -> DEL | K33: =IFERROR(INDEX(B7:B41,MATCH(LARGE(O7:O41,27),O7:O41,0)),"–") -> Delaminace (hrany) | L33: =IFERROR(INDEX(C7:C41,MATCH(LARGE(O7:O41,27),O7:O41,0)),0) -> 0 | M33: =IFERROR(L33/C42,0) -> 0 | N33: =SUM($M$7:M33) -> 1 | O33: =C33+(1-ROW()*0.00001) -> 0.99967
A34: PSHC | B34: Špatný heating spacer | C34: =SUMPRODUCT(('Posouzení PREFIX'!AK6:AK205<>"")*('Posouzení PREFIX'!A6:A205<>"")*IF($B$2="Vše",1,'Posouzení PREFIX'!AW6:AW205=MATCH($B$2,{"Leden","Únor","Březen","Duben","Květen","Červen","Červenec","Srpen","Září","Říjen","Listopad","Prosinec"},0))*IF($B$3="Vše",1,'Posouzení PREFIX'!AX6:AX205=VALUE($B$3))) -> 0 | D34: =IF(C42>0,C34/C42,0) -> 0 | E34: =SUM($D$7:D34) -> 0.41697417 | F34: =IFERROR(RANK(C34,C$7:C$41,0),"") -> 21 | I34: 28 | J34: =IFERROR(INDEX(A7:A41,MATCH(LARGE(O7:O41,28),O7:O41,0)),"–") -> PDEL | K34: =IFERROR(INDEX(B7:B41,MATCH(LARGE(O7:O41,28),O7:O41,0)),"–") -> Delaminace (plochy) | L34: =IFERROR(INDEX(C7:C41,MATCH(LARGE(O7:O41,28),O7:O41,0)),0) -> 0 | M34: =IFERROR(L34/C42,0) -> 0 | N34: =SUM($M$7:M34) -> 1 | O34: =C34+(1-ROW()*0.00001) -> 0.99966
A35: PSMC | B35: Špatný plastový MC | C35: =SUMPRODUCT(('Posouzení PREFIX'!AL6:AL205<>"")*('Posouzení PREFIX'!A6:A205<>"")*IF($B$2="Vše",1,'Posouzení PREFIX'!AW6:AW205=MATCH($B$2,{"Leden","Únor","Březen","Duben","Květen","Červen","Červenec","Srpen","Září","Říjen","Listopad","Prosinec"},0))*IF($B$3="Vše",1,'Posouzení PREFIX'!AX6:AX205=VALUE($B$3))) -> 0 | D35: =IF(C42>0,C35/C42,0) -> 0 | E35: =SUM($D$7:D35) -> 0.41697417 | F35: =IFERROR(RANK(C35,C$7:C$41,0),"") -> 21 | I35: 29 | J35: =IFERROR(INDEX(A7:A41,MATCH(LARGE(O7:O41,29),O7:O41,0)),"–") -> ZNA | K35: =IFERROR(INDEX(B7:B41,MATCH(LARGE(O7:O41,29),O7:O41,0)),"–") -> Znečištění od ASQ | L35: =IFERROR(INDEX(C7:C41,MATCH(LARGE(O7:O41,29),O7:O41,0)),0) -> 0 | M35: =IFERROR(L35/C42,0) -> 0 | N35: =SUM($M$7:M35) -> 1 | O35: =C35+(1-ROW()*0.00001) -> 0.99965
A36: PELS | B36: Expirované lepidlo na spaceru | C36: =SUMPRODUCT(('Posouzení PREFIX'!AN6:AN205<>"")*('Posouzení PREFIX'!A6:A205<>"")*IF($B$2="Vše",1,'Posouzení PREFIX'!AW6:AW205=MATCH($B$2,{"Leden","Únor","Březen","Duben","Květen","Červen","Červenec","Srpen","Září","Říjen","Listopad","Prosinec"},0))*IF($B$3="Vše",1,'Posouzení PREFIX'!AX6:AX205=VALUE($B$3))) -> 0 | D36: =IF(C42>0,C36/C42,0) -> 0 | E36: =SUM($D$7:D36) -> 0.41697417 | F36: =IFERROR(RANK(C36,C$7:C$41,0),"") -> 21 | I36: 30 | J36: =IFERROR(INDEX(A7:A41,MATCH(LARGE(O7:O41,30),O7:O41,0)),"–") -> FLEK | K36: =IFERROR(INDEX(B7:B41,MATCH(LARGE(O7:O41,30),O7:O41,0)),"–") -> Flek | L36: =IFERROR(INDEX(C7:C41,MATCH(LARGE(O7:O41,30),O7:O41,0)),0) -> 0 | M36: =IFERROR(L36/C42,0) -> 0 | N36: =SUM($M$7:M36) -> 1 | O36: =C36+(1-ROW()*0.00001) -> 0.99964
A37: PSGL | B37: Špatná gramáž lepidla | C37: =SUMPRODUCT(('Posouzení PREFIX'!AP6:AP205<>"")*('Posouzení PREFIX'!A6:A205<>"")*IF($B$2="Vše",1,'Posouzení PREFIX'!AW6:AW205=MATCH($B$2,{"Leden","Únor","Březen","Duben","Květen","Červen","Červenec","Srpen","Září","Říjen","Listopad","Prosinec"},0))*IF($B$3="Vše",1,'Posouzení PREFIX'!AX6:AX205=VALUE($B$3))) -> 1 | D37: =IF(C42>0,C37/C42,0) -> 0.0018450185 | E37: =SUM($D$7:D37) -> 0.41881919 | F37: =IFERROR(RANK(C37,C$7:C$41,0),"") -> 17 | I37: 31 | J37: =IFERROR(INDEX(A7:A41,MATCH(LARGE(O7:O41,31),O7:O41,0)),"–") -> PSKZ | K37: =IFERROR(INDEX(B7:B41,MATCH(LARGE(O7:O41,31),O7:O41,0)),"–") -> Špatná kůže | L37: =IFERROR(INDEX(C7:C41,MATCH(LARGE(O7:O41,31),O7:O41,0)),0) -> 0 | M37: =IFERROR(L37/C42,0) -> 0 | N37: =SUM($M$7:M37) -> 1 | O37: =C37+(1-ROW()*0.00001) -> 1.99963
A38: PSAL | B38: Špatně aktivované lepidlo | C38: =SUMPRODUCT(('Posouzení PREFIX'!AS6:AS205<>"")*('Posouzení PREFIX'!A6:A205<>"")*IF($B$2="Vše",1,'Posouzení PREFIX'!AW6:AW205=MATCH($B$2,{"Leden","Únor","Březen","Duben","Květen","Červen","Červenec","Srpen","Září","Říjen","Listopad","Prosinec"},0))*IF($B$3="Vše",1,'Posouzení PREFIX'!AX6:AX205=VALUE($B$3))) -> 0 | D38: =IF(C42>0,C38/C42,0) -> 0 | E38: =SUM($D$7:D38) -> 0.41881919 | F38: =IFERROR(RANK(C38,C$7:C$41,0),"") -> 21 | I38: 32 | J38: =IFERROR(INDEX(A7:A41,MATCH(LARGE(O7:O41,32),O7:O41,0)),"–") -> PSHC | K38: =IFERROR(INDEX(B7:B41,MATCH(LARGE(O7:O41,32),O7:O41,0)),"–") -> Špatný heating spacer | L38: =IFERROR(INDEX(C7:C41,MATCH(LARGE(O7:O41,32),O7:O41,0)),0) -> 0 | M38: =IFERROR(L38/C42,0) -> 0 | N38: =SUM($M$7:M38) -> 1 | O38: =C38+(1-ROW()*0.00001) -> 0.99962
A39: KRSW | B39: Kragujevac - sewing | C39: =SUMPRODUCT(('Posouzení PREFIX'!AT6:AT205<>"")*('Posouzení PREFIX'!A6:A205<>"")*IF($B$2="Vše",1,'Posouzení PREFIX'!AW6:AW205=MATCH($B$2,{"Leden","Únor","Březen","Duben","Květen","Červen","Červenec","Srpen","Září","Říjen","Listopad","Prosinec"},0))*IF($B$3="Vše",1,'Posouzení PREFIX'!AX6:AX205=VALUE($B$3))) -> 36 | D39: =IF(C42>0,C39/C42,0) -> 0.066420664 | E39: =SUM($D$7:D39) -> 0.48523985 | F39: =IFERROR(RANK(C39,C$7:C$41,0),"") -> 4 | I39: 33 | J39: =IFERROR(INDEX(A7:A41,MATCH(LARGE(O7:O41,33),O7:O41,0)),"–") -> PSMC | K39: =IFERROR(INDEX(B7:B41,MATCH(LARGE(O7:O41,33),O7:O41,0)),"–") -> Špatný plastový MC | L39: =IFERROR(INDEX(C7:C41,MATCH(LARGE(O7:O41,33),O7:O41,0)),0) -> 0 | M39: =IFERROR(L39/C42,0) -> 0 | N39: =SUM($M$7:M39) -> 1 | O39: =C39+(1-ROW()*0.00001) -> 36.99961
A40: KRSK | B40: Kragujevac - skin defect | C40: =SUMPRODUCT(('Posouzení PREFIX'!AU6:AU205<>"")*('Posouzení PREFIX'!A6:A205<>"")*IF($B$2="Vše",1,'Posouzení PREFIX'!AW6:AW205=MATCH($B$2,{"Leden","Únor","Březen","Duben","Květen","Červen","Červenec","Srpen","Září","Říjen","Listopad","Prosinec"},0))*IF($B$3="Vše",1,'Posouzení PREFIX'!AX6:AX205=VALUE($B$3))) -> 167 | D40: =IF(C42>0,C40/C42,0) -> 0.30811808 | E40: =SUM($D$7:D40) -> 0.79335793 | F40: =IFERROR(RANK(C40,C$7:C$41,0),"") -> 1 | I40: 34 | J40: =IFERROR(INDEX(A7:A41,MATCH(LARGE(O7:O41,34),O7:O41,0)),"–") -> PELS | K40: =IFERROR(INDEX(B7:B41,MATCH(LARGE(O7:O41,34),O7:O41,0)),"–") -> Expirované lepidlo na spaceru | L40: =IFERROR(INDEX(C7:C41,MATCH(LARGE(O7:O41,34),O7:O41,0)),0) -> 0 | M40: =IFERROR(L40/C42,0) -> 0 | N40: =SUM($M$7:M40) -> 1 | O40: =C40+(1-ROW()*0.00001) -> 167.9996
A41: KRSS | B41: Kragujevac - short skin | C41: =SUMPRODUCT(('Posouzení PREFIX'!AV6:AV205<>"")*('Posouzení PREFIX'!A6:A205<>"")*IF($B$2="Vše",1,'Posouzení PREFIX'!AW6:AW205=MATCH($B$2,{"Leden","Únor","Březen","Duben","Květen","Červen","Červenec","Srpen","Září","Říjen","Listopad","Prosinec"},0))*IF($B$3="Vše",1,'Posouzení PREFIX'!AX6:AX205=VALUE($B$3))) -> 112 | D41: =IF(C42>0,C41/C42,0) -> 0.20664207 | E41: =SUM($D$7:D41) -> 1 | F41: =IFERROR(RANK(C41,C$7:C$41,0),"") -> 2 | I41: 35 | J41: =IFERROR(INDEX(A7:A41,MATCH(LARGE(O7:O41,35),O7:O41,0)),"–") -> PSAL | K41: =IFERROR(INDEX(B7:B41,MATCH(LARGE(O7:O41,35),O7:O41,0)),"–") -> Špatně aktivované lepidlo | L41: =IFERROR(INDEX(C7:C41,MATCH(LARGE(O7:O41,35),O7:O41,0)),0) -> 0 | M41: =IFERROR(L41/C42,0) -> 0 | N41: =SUM($M$7:M41) -> 1 | O41: =C41+(1-ROW()*0.00001) -> 112.99959
A42: CELKEM | C42: =SUM(C7:C41) -> 542 | L42: =SUM(L7:L41) -> 542

Sheet Pareto SKLAD
A1: Pareto graf – SKLAD
A2: Filtrovat dle měsíce: | B2: Vše | E2: ← vyberte měsíc nebo nechte 'Vše'
